<mujoco model="R2">
  <compiler angle="radian" meshdir="meshes/"/>

  <default>
    <equality solref='0.001 2'/>
    <joint damping="0.001" armature="0.001" frictionloss="0.001" limited='true'/>
  </default>
  
  <asset>
    <mesh name="base_link" file="base_clump_weight_link.STL"/>
    <mesh name="clump_weight_link" file="clump_weight_link.STL"/>
    <mesh name="left_hip_pitch_link" file="left_hip_pitch_link.STL"/>
    <mesh name="left_hip_roll_link" file="left_hip_roll_link.STL"/>
    <mesh name="left_hip_yaw_link" file="left_hip_yaw_link.STL"/>
    <mesh name="left_knee_link" file="left_knee_link.STL"/>
    <mesh name="left_ankle_pitch_link" file="left_ankle_pitch_link.STL"/>
    <mesh name="left_ankle_roll_arch_link" file="left_ankle_roll_arch_link.STL"/>
    <mesh name="right_hip_pitch_link" file="right_hip_pitch_link.STL"/>
    <mesh name="right_hip_roll_link" file="right_hip_roll_link.STL"/>
    <mesh name="right_hip_yaw_link" file="right_hip_yaw_link.STL"/>
    <mesh name="right_knee_link" file="right_knee_link.STL"/>
    <mesh name="right_ankle_pitch_link" file="right_ankle_pitch_link.STL"/>
    <mesh name="right_ankle_roll_arch_link" file="right_ankle_roll_arch_link.STL"/>

    <texture type="skybox" builtin="flat" rgb1="0 0 0" rgb2="0 0 0" width="512" height="3072"/>
    <texture type="2d" name="groundplane" builtin="checker" mark="edge" rgb1="0.2 0.3 0.4" rgb2="0.1 0.2 0.3" markrgb="0.8 0.8 0.8" width="300" height="300"/>
    <material name="groundplane" texture="groundplane" texuniform="true" texrepeat="5 5" reflectance="0.2"/>
  </asset>

  <worldbody>
    <light pos="1 0 3.5" dir="0 0 -1" directional="true"/>
    <geom name="floor" size="0 0 0.05" type="plane" material="groundplane"/>
    <body name="base_link" pos="0.0 0.0 0.665">
      <inertial pos="0.00439618 5.853e-05 0.0065115" quat="0.995389 -0.00303862 0.0958618 0.00137922" mass="2.61" diaginertia="0.00684226 0.00529172 0.00495773"/>
      <joint name="floating_base_joint" type="free" limited="false"/>
      <site name='imu_in_base' size='0.01' pos='0.0059965 -0.003397 -0.070175'/>

      <geom type="mesh" contype="0" conaffinity="0" group="1" density="0" rgba="0.69804 0.69804 0.69804 1" mesh="base_link"/>
      <geom type="mesh" rgba="0.69804 0.69804 0.69804 1" mesh="base_link"/>
      <body name="clump_weight_link" pos="0.02025 -0.000208559 0.112125">
        <inertial pos="-0.0006442 -7.046e-05 0.0517855" quat="0.485219 0.481295 -0.518456 0.513927" mass="18.0293" diaginertia="0.0689299 0.05783 0.0496081"/>
        <geom type="mesh" contype="0" conaffinity="0" group="1" density="0" rgba="0.69804 0.69804 0.69804 1" mesh="clump_weight_link"/>
        <geom type="mesh" rgba="0.69804 0.69804 0.69804 1" mesh="clump_weight_link" />
      </body>
      <body name="left_hip_pitch_link" pos="0 0.05845 0">
        <inertial pos="-0.00028938 0.0552098 0.00013118" quat="0.624 0.762626 -0.100952 0.137241" mass="1.213" diaginertia="0.00196429 0.00126426 0.00118545"/>
        <joint name="left_hip_pitch_joint" pos="0 0 0" axis="0 1 0" range="-2.53073 2.87979"/>
        <geom type="mesh" contype="0" conaffinity="0" group="1" density="0" rgba="0.698039 0.698039 0.698039 1" mesh="left_hip_pitch_link"/>
        <geom type="mesh" rgba="0.698039 0.698039 0.698039 1" mesh="left_hip_pitch_link"/>
        <body name="left_hip_roll_link" pos="0.0249723 0.0615 0.00908931" quat="0.984808 0 -0.173648 0">
          <inertial pos="-0.0160996 -1.412e-05 -0.0785425" quat="0.970996 0.00709152 0.237872 0.023102" mass="1.41" diaginertia="0.00387609 0.00366692 0.00179032"/>
          <joint name="left_hip_roll_joint" pos="0 0 0" axis="1 0 0" range="-0.2618 2.4435"/>
          <geom type="mesh" contype="0" conaffinity="0" group="1" density="0" rgba="0.698039 0.698039 0.698039 1" mesh="left_hip_roll_link"/>
          <geom type="mesh" rgba="0.698039 0.698039 0.698039 1" mesh="left_hip_roll_link"/>
          <body name="left_hip_yaw_link" pos="-0.02675 0 -0.1225">
            <inertial pos="-0.0474191 -0.00321393 -0.155731" quat="0.682927 0.149345 0.163897 0.696021" mass="2.338" diaginertia="0.014732 0.0121792 0.00352749"/>
            <joint name="left_hip_yaw_joint" pos="0 0 0" axis="0 0 1" range="-2.7576 2.7576"/>
            <geom type="mesh" contype="0" conaffinity="0" group="1" density="0" rgba="0.698039 0.698039 0.698039 1" mesh="left_hip_yaw_link"/>
            <geom type="mesh" rgba="0.698039 0.698039 0.698039 1" mesh="left_hip_yaw_link"/>
            <body name="left_knee_link" pos="-0.066694 0.02125 -0.18724" quat="0.984807 0 0.17365 0">
              <inertial pos="-0.00155103 -0.0169997 -0.135639" quat="0.992676 -0.047992 -0.000255522 -0.110866" mass="1.77" diaginertia="0.00872659 0.00870407 0.000975052"/>
              <joint name="left_knee_joint" pos="0 0 0" axis="0 1 0" range="-0.401426 2.42601"/>
              <geom type="mesh" contype="0" conaffinity="0" group="1" density="0" rgba="0.698039 0.698039 0.698039 1" mesh="left_knee_link"/>
              <geom type="mesh" rgba="0.698039 0.698039 0.698039 1" mesh="left_knee_link"/>
              <body name="left_ankle_pitch_link" pos="0.00014288 -0.02125 -0.298" quat="1 0 -0.000239735 0">
                <inertial pos="-0.00174962 0 -0.0115014" quat="0.601391 0.371926 0.371926 0.601391" mass="0.096984" diaginertia="2.495e-05 1.6474e-05 1.3096e-05"/>
                <joint name="left_ankle_pitch_joint" pos="0 0 0" axis="0 1 0" range="-0.69813 0.5236"/>
                <geom type="mesh" contype="0" conaffinity="0" group="1" density="0" rgba="0.752941 0.752941 0.752941 1" mesh="left_ankle_pitch_link"/>
                <geom type="mesh" rgba="0.752941 0.752941 0.752941 1" mesh="left_ankle_pitch_link"/>
                <body name="left_ankle_roll_link" pos="0 0 -0.02">
                  <inertial pos="0.00993838 -0.00011106 -0.0107838" quat="-0.0225578 0.731527 -0.0110743 0.681349" mass="0.492604" diaginertia="0.00101967 0.000975662 0.00016946"/>
                  <joint name="left_ankle_roll_joint" pos="0 0 0" axis="1 0 0" range="-0.2618 0.2618"/>
                  <geom type="mesh" contype="0" conaffinity="0" group="1" density="0" rgba="0.698039 0.698039 0.698039 1" mesh="left_ankle_roll_arch_link"/>
                  <geom size="0.005" pos="-0.05 -0.028 -0.025" rgba="0.698039 0.698039 0.698039 1"/>
                  <geom size="0.005" pos="-0.05 0.0185 -0.025" rgba="0.698039 0.698039 0.698039 1"/>
                  <geom size="0.005" pos="0.1 -0.026 -0.025" rgba="0.698039 0.698039 0.698039 1"/>
                  <geom size="0.005" pos="0.1 0.024 -0.025" rgba="0.698039 0.698039 0.698039 1"/>
                </body>
              </body>
            </body>
          </body>
        </body>
      </body>
      <body name="right_hip_pitch_link" pos="0 -0.05845 0">
        <inertial pos="-0.00029784 -0.0548362 0.0002104" quat="0.766944 0.619123 -0.13638 0.0994193" mass="1.213" diaginertia="0.00196518 0.00126368 0.00118772"/>
        <joint name="right_hip_pitch_joint" pos="0 0 0" axis="0 1 0" range="-2.53073 2.87979"/>
        <geom type="mesh" contype="0" conaffinity="0" group="1" density="0" rgba="0.698039 0.698039 0.698039 1" mesh="right_hip_pitch_link"/>
        <geom type="mesh" rgba="0.698039 0.698039 0.698039 1" mesh="right_hip_pitch_link"/>
        <body name="right_hip_roll_link" pos="0.0249724 -0.0611 0.00908906" quat="0.984808 0 -0.173648 0">
          <inertial pos="-0.0160996 -1.412e-05 -0.0785425" quat="0.970996 0.00709152 0.237872 0.023102" mass="1.41" diaginertia="0.00387609 0.00366692 0.00179032"/>
          <joint name="right_hip_roll_joint" pos="0 0 0" axis="1 0 0" range="-2.4435 0.2618"/>
          <geom type="mesh" contype="0" conaffinity="0" group="1" density="0" rgba="0.698039 0.698039 0.698039 1" mesh="right_hip_roll_link"/>
          <geom type="mesh" rgba="0.698039 0.698039 0.698039 1" mesh="right_hip_roll_link"/>
          <body name="right_hip_yaw_link" pos="-0.02675 0 -0.1225">
            <inertial pos="-0.047435 0.00321447 -0.155724" quat="0.696059 0.164039 0.149531 0.682813" mass="2.338" diaginertia="0.0147327 0.01218 0.00352727"/>
            <joint name="right_hip_yaw_joint" pos="0 0 0" axis="0 0 1" range="-2.7576 2.7576"/>
            <geom type="mesh" contype="0" conaffinity="0" group="1" density="0" rgba="0.698039 0.698039 0.698039 1" mesh="right_hip_yaw_link"/>
            <geom type="mesh" rgba="0.698039 0.698039 0.698039 1" mesh="right_hip_yaw_link"/>
            <body name="right_knee_link" pos="-0.066694 -0.02125 -0.18724" quat="0.984807 0 0.17365 0">
              <inertial pos="-0.00155151 0.0170012 -0.13564" quat="0.99326 0.0479889 3.33999e-06 0.105504" mass="1.771" diaginertia="0.00873081 0.00870836 0.00097571"/>
              <joint name="right_knee_joint" pos="0 0 0" axis="0 1 0" range="-0.401426 2.42601"/>
              <geom type="mesh" contype="0" conaffinity="0" group="1" density="0" rgba="0.698039 0.698039 0.698039 1" mesh="right_knee_link"/>
              <geom type="mesh" rgba="0.698039 0.698039 0.698039 1" mesh="right_knee_link"/>
              <body name="right_ankle_pitch_link" pos="0.000142882 0.02125 -0.298" quat="1 0 -0.000239736 0">
                <inertial pos="-0.00174962 0 -0.0115014" quat="0.601391 0.371926 0.371926 0.601391" mass="0.096984" diaginertia="2.495e-05 1.6474e-05 1.3096e-05"/>
                <joint name="right_ankle_pitch_joint" pos="0 0 0" axis="0 1 0" range="-0.69813 0.5236"/>
                <geom type="mesh" contype="0" conaffinity="0" group="1" density="0" rgba="0.752941 0.752941 0.752941 1" mesh="right_ankle_pitch_link"/>
                <geom type="mesh" rgba="0.752941 0.752941 0.752941 1" mesh="right_ankle_pitch_link"/>
                <body name="right_ankle_roll_link" pos="0 0 -0.02">
                  <inertial pos="0.00994096 0.00011084 -0.0107841" quat="0.0225581 0.731532 0.0110863 0.681344" mass="0.492613" diaginertia="0.00101978 0.000975801 0.000169458"/>
                  <joint name="right_ankle_roll_joint" pos="0 0 0" axis="1 0 0" range="-0.2618 0.2618"/>
                  <geom type="mesh" contype="0" conaffinity="0" group="1" density="0" rgba="0.698039 0.698039 0.698039 1" mesh="right_ankle_roll_arch_link"/>
                  <geom size="0.005" pos="-0.05 0.028 -0.025" rgba="0.698039 0.698039 0.698039 1"/>
                  <geom size="0.005" pos="-0.05 -0.0185 -0.025" rgba="0.698039 0.698039 0.698039 1"/>
                  <geom size="0.005" pos="0.1 0.026 -0.025" rgba="0.698039 0.698039 0.698039 1"/>
                  <geom size="0.005" pos="0.1 -0.024 -0.025" rgba="0.698039 0.698039 0.698039 1"/>
                </body>
              </body>
            </body>
          </body>
        </body>
      </body>
    </body>
  </worldbody>
  <actuator>
    <motor name="left_hip_pitch_joint" joint="left_hip_pitch_joint" gear="1" ctrllimited="true" ctrlrange="-130 130"/>
    <motor name="left_hip_roll_joint" joint="left_hip_roll_joint" gear="1" ctrllimited="true" ctrlrange="-130 130"/>
    <motor name="left_hip_yaw_joint" joint="left_hip_yaw_joint" gear="1" ctrllimited="true" ctrlrange="-90 90"/>
    <motor name="left_knee_joint" joint="left_knee_joint" gear="1" ctrllimited="true" ctrlrange="-150 150"/>
    <motor name="left_ankle_pitch_joint" joint="left_ankle_pitch_joint" gear="1" ctrllimited="true" ctrlrange="-75 75"/>
    <motor name="left_ankle_roll_joint" joint="left_ankle_roll_joint" gear="1" ctrllimited="true" ctrlrange="-75 75"/>

    <motor name="right_hip_pitch_joint" joint="right_hip_pitch_joint" gear="1" ctrllimited="true" ctrlrange="-130 130"/>
    <motor name="right_hip_roll_joint" joint="right_hip_roll_joint" gear="1" ctrllimited="true" ctrlrange="-130 130"/>
    <motor name="right_hip_yaw_joint" joint="right_hip_yaw_joint" gear="1" ctrllimited="true" ctrlrange="-90 90"/>
    <motor name="right_knee_joint" joint="right_knee_joint" gear="1" ctrllimited="true" ctrlrange="-150 150"/>
    <motor name="right_ankle_pitch_joint" joint="right_ankle_pitch_joint" gear="1" ctrllimited="true" ctrlrange="-75 75"/>
    <motor name="right_ankle_roll_joint" joint="right_ankle_roll_joint" gear="1" ctrllimited="true" ctrlrange="-75 75"/>
  </actuator>

  <sensor>
    <framequat name='orientation' objtype='site' noise='0.001' objname='imu_in_base'/>
    <framepos name='position' objtype='site' noise='0.001' objname='imu_in_base'/>
    <gyro name='angular-velocity' site='imu_in_base' noise='0.005' cutoff='34.9'/>
    <velocimeter name='linear-velocity' site='imu_in_base' noise='0.001' cutoff='30'/>
    <accelerometer name='linear-acceleration' site='imu_in_base' noise='0.005' cutoff='157'/>
    <magnetometer name='magnetometer' site='imu_in_base'/>
  </sensor>

</mujoco>
