<mujoco model="R2">
  <compiler angle="radian" meshdir="meshes/"/>
  
  <default>
    <equality solref='0.001 2'/>
    <joint damping="0.001" armature="0.01" frictionloss="0.001" limited='true'/>
  </default>

  <asset>
    <mesh name="base_link" file="base_link.STL"/>
    <mesh name="left_hip_pitch_link" file="left_hip_pitch_link.STL"/>
    <mesh name="left_hip_roll_link" file="left_hip_roll_link.STL"/>
    <mesh name="left_hip_yaw_link" file="left_hip_yaw_link.STL"/>
    <mesh name="left_knee_link" file="left_knee_link.STL"/>
    <mesh name="left_ankle_pitch_link" file="left_ankle_pitch_link.STL"/>
    <mesh name="left_ankle_roll_link" file="left_ankle_roll_link.STL"/>
    <mesh name="right_hip_pitch_link" file="right_hip_pitch_link.STL"/>
    <mesh name="right_hip_roll_link" file="right_hip_roll_link.STL"/>
    <mesh name="right_hip_yaw_link" file="right_hip_yaw_link.STL"/>
    <mesh name="right_knee_link" file="right_knee_link.STL"/>
    <mesh name="right_ankle_pitch_link" file="right_ankle_pitch_link.STL"/>
    <mesh name="right_ankle_roll_link" file="right_ankle_roll_link.STL"/>
    <mesh name="waist_yaw_link" file="waist_yaw_link.STL"/>
    <mesh name="waist_pitch_link" file="waist_pitch_link.STL"/>
    <mesh name="left_shoulder_pitch_link" file="left_shoulder_pitch_link.STL"/>
    <mesh name="left_shoulder_roll_link" file="left_shoulder_roll_link.STL"/>
    <mesh name="left_shoulder_yaw_link" file="left_shoulder_yaw_link.STL"/>
    <mesh name="left_arm_pitch_link" file="left_arm_pitch_link.STL"/>
    <mesh name="right_shoulder_pitch_link" file="right_shoulder_pitch_link.STL"/>
    <mesh name="right_shoulder_roll_link" file="right_shoulder_roll_link.STL"/>
    <mesh name="right_shoulder_yaw_link" file="right_shoulder_yaw_link.STL"/>
    <mesh name="right_arm_pitch_link" file="right_arm_pitch_link.STL"/>

    <texture type="skybox" builtin="flat" rgb1="0 0 0" rgb2="0 0 0" width="512" height="3072"/>
    <texture type="2d" name="groundplane" builtin="checker" mark="edge" rgb1="0.2 0.3 0.4" rgb2="0.1 0.2 0.3" markrgb="0.8 0.8 0.8" width="300" height="300"/>
    <material name="groundplane" texture="groundplane" texuniform="true" texrepeat="5 5" reflectance="0.2"/>
  </asset>

  <worldbody>
    <light pos="1 0 3.5" dir="0 0 -1" directional="true"/>
    <geom name="floor" size="0 0 0.05" type="plane" material="groundplane"/>
    <body name="base_link" pos="0.0 0.0 0.665">
      <inertial pos="0.00327496 2.04e-06 0.0337905" quat="0.99997 0.0015126 0.00763429 0.000442661" mass="3.335" diaginertia="0.0126196 0.0112879 0.00585432"/>
      <joint name="floating_base_joint" type="free" limited="false"/>
      <site name='imu_in_base' size='0.01' pos='0.0059965 -0.003397 -0.070175'/>

      <geom type="mesh" contype="0" conaffinity="0" group="1" density="0" rgba="0.69804 0.69804 0.69804 1" mesh="base_link"/>
      <geom type="mesh" rgba="0.69804 0.69804 0.69804 1" mesh="base_link"/>
      <body name="left_hip_pitch_link" pos="0 0.05845 0">
        <inertial pos="-0.00028938 0.0552098 0.00013118" quat="0.624 0.762626 -0.100952 0.137241" mass="1.213" diaginertia="0.00196429 0.00126426 0.00118545"/>
        <joint name="left_hip_pitch_joint" pos="0 0 0" axis="0 1 0" range="-2.53073 2.87979"/>
        <geom type="mesh" contype="0" conaffinity="0" group="1" density="0" rgba="0.698039 0.698039 0.698039 1" mesh="left_hip_pitch_link"/>
        <geom type="mesh" rgba="0.698039 0.698039 0.698039 1" mesh="left_hip_pitch_link"/>
        <body name="left_hip_roll_link" pos="0.0249723 0.0615 0.00908931" quat="0.984808 0 -0.173648 0">
          <inertial pos="-0.0160996 -1.412e-05 -0.0785425" quat="0.970996 0.00709152 0.237872 0.023102" mass="1.41" diaginertia="0.00387609 0.00366692 0.00179032"/>
          <joint name="left_hip_roll_joint" pos="0 0 0" axis="1 0 0" range="-0.2618 2.4435"/>
          <geom type="mesh" contype="0" conaffinity="0" group="1" density="0" rgba="0.698039 0.698039 0.698039 1" mesh="left_hip_roll_link"/>
          <geom type="mesh" rgba="0.698039 0.698039 0.698039 1" mesh="left_hip_roll_link"/>
          <body name="left_hip_yaw_link" pos="-0.02675 0 -0.1225">
            <inertial pos="-0.0474191 -0.00321393 -0.155731" quat="0.682927 0.149345 0.163897 0.696021" mass="2.338" diaginertia="0.014732 0.0121792 0.00352749"/>
            <joint name="left_hip_yaw_joint" pos="0 0 0" axis="0 0 1" range="-2.7576 2.7576"/>
            <geom type="mesh" contype="0" conaffinity="0" group="1" density="0" rgba="0.698039 0.698039 0.698039 1" mesh="left_hip_yaw_link"/>
            <geom type="mesh" rgba="0.698039 0.698039 0.698039 1" mesh="left_hip_yaw_link"/>
            <body name="left_knee_link" pos="-0.066694 0.02125 -0.18724" quat="0.984807 0 0.17365 0">
              <inertial pos="-0.00155103 -0.0169997 -0.135639" quat="0.992676 -0.047992 -0.000255522 -0.110866" mass="1.77" diaginertia="0.00872659 0.00870407 0.000975052"/>
              <joint name="left_knee_joint" pos="0 0 0" axis="0 1 0" range="-0.401426 2.42601"/>
              <geom type="mesh" contype="0" conaffinity="0" group="1" density="0" rgba="0.698039 0.698039 0.698039 1" mesh="left_knee_link"/>
              <geom type="mesh" rgba="0.698039 0.698039 0.698039 1" mesh="left_knee_link"/>
              <body name="left_ankle_pitch_link" pos="0.00014288 -0.02125 -0.298" quat="1 0 -0.000239735 0">
                <inertial pos="-0.00174962 0 -0.0115014" quat="0.601391 0.371926 0.371926 0.601391" mass="0.096984" diaginertia="2.495e-05 1.6474e-05 1.3096e-05"/>
                <joint name="left_ankle_pitch_joint" pos="0 0 0" axis="0 1 0" range="-0.69813 0.5236"/>
                <geom type="mesh" contype="0" conaffinity="0" group="1" density="0" rgba="0.752941 0.752941 0.752941 1" mesh="left_ankle_pitch_link"/>
                <geom type="mesh" rgba="0.752941 0.752941 0.752941 1" mesh="left_ankle_pitch_link"/>
                <body name="left_ankle_roll_link" pos="0 0 -0.02">
                  <inertial pos="0.0216765 3.015e-05 -0.0188986" quat="0.000202855 0.723222 0.000416846 0.690615" mass="0.554" diaginertia="0.0017197 0.00154568 0.000279609"/>
                  <joint name="left_ankle_roll_joint" pos="0 0 0" axis="1 0 0" range="-0.2618 0.2618"/>
                  <geom type="mesh" contype="0" conaffinity="0" group="1" density="0" rgba="0.698039 0.698039 0.698039 1" mesh="left_ankle_roll_link"/>
                  <geom size="0.005" pos="-0.05 0.025 -0.025" rgba="0.698039 0.698039 0.698039 1"/>
                  <geom size="0.005" pos="-0.05 -0.025 -0.025" rgba="0.698039 0.698039 0.698039 1"/>
                  <geom size="0.005" pos="0.12 0.03 -0.025" rgba="0.698039 0.698039 0.698039 1"/>
                  <geom size="0.005" pos="0.12 -0.03 -0.025" rgba="0.698039 0.698039 0.698039 1"/>
                </body>
              </body>
            </body>
          </body>
        </body>
      </body>
      <body name="right_hip_pitch_link" pos="0 -0.05845 0">
        <inertial pos="-0.00029784 -0.0548362 0.0002104" quat="0.766944 0.619123 -0.13638 0.0994193" mass="1.213" diaginertia="0.00196518 0.00126368 0.00118772"/>
        <joint name="right_hip_pitch_joint" pos="0 0 0" axis="0 1 0" range="-2.53073 2.87979"/>
        <geom type="mesh" contype="0" conaffinity="0" group="1" density="0" rgba="0.698039 0.698039 0.698039 1" mesh="right_hip_pitch_link"/>
        <geom type="mesh" rgba="0.698039 0.698039 0.698039 1" mesh="right_hip_pitch_link"/>
        <body name="right_hip_roll_link" pos="0.0249724 -0.0611 0.00908906" quat="0.984808 0 -0.173648 0">
          <inertial pos="-0.0160996 -1.412e-05 -0.0785425" quat="0.970996 0.00709152 0.237872 0.023102" mass="1.41" diaginertia="0.00387609 0.00366692 0.00179032"/>
          <joint name="right_hip_roll_joint" pos="0 0 0" axis="1 0 0" range="-2.4435 0.2618"/>
          <geom type="mesh" contype="0" conaffinity="0" group="1" density="0" rgba="0.698039 0.698039 0.698039 1" mesh="right_hip_roll_link"/>
          <geom type="mesh" rgba="0.698039 0.698039 0.698039 1" mesh="right_hip_roll_link"/>
          <body name="right_hip_yaw_link" pos="-0.02675 0 -0.1225">
            <inertial pos="-0.047435 0.00321447 -0.155724" quat="0.696059 0.164039 0.149531 0.682813" mass="2.338" diaginertia="0.0147327 0.01218 0.00352727"/>
            <joint name="right_hip_yaw_joint" pos="0 0 0" axis="0 0 1" range="-2.7576 2.7576"/>
            <geom type="mesh" contype="0" conaffinity="0" group="1" density="0" rgba="0.698039 0.698039 0.698039 1" mesh="right_hip_yaw_link"/>
            <geom type="mesh" rgba="0.698039 0.698039 0.698039 1" mesh="right_hip_yaw_link"/>
            <body name="right_knee_link" pos="-0.066694 -0.02125 -0.18724" quat="0.984807 0 0.17365 0">
              <inertial pos="-0.00155151 0.0170012 -0.13564" quat="0.99326 0.0479889 3.33999e-06 0.105504" mass="1.771" diaginertia="0.00873081 0.00870836 0.00097571"/>
              <joint name="right_knee_joint" pos="0 0 0" axis="0 1 0" range="-0.401426 2.42601"/>
              <geom type="mesh" contype="0" conaffinity="0" group="1" density="0" rgba="0.698039 0.698039 0.698039 1" mesh="right_knee_link"/>
              <geom type="mesh" rgba="0.698039 0.698039 0.698039 1" mesh="right_knee_link"/>
              <body name="right_ankle_pitch_link" pos="0.000142882 0.02125 -0.298" quat="1 0 -0.000239736 0">
                <inertial pos="-0.00174962 0 -0.0115014" quat="0.601391 0.371926 0.371926 0.601391" mass="0.096984" diaginertia="2.495e-05 1.6474e-05 1.3096e-05"/>
                <joint name="right_ankle_pitch_joint" pos="0 0 0" axis="0 1 0" range="-0.69813 0.5236"/>
                <geom type="mesh" contype="0" conaffinity="0" group="1" density="0" rgba="0.752941 0.752941 0.752941 1" mesh="right_ankle_pitch_link"/>
                <geom type="mesh" rgba="0.752941 0.752941 0.752941 1" mesh="right_ankle_pitch_link"/>
                <body name="right_ankle_roll_link" pos="0 0 -0.02">
                  <inertial pos="0.0217157 3.14e-05 -0.0189203" quat="0.00017822 0.723066 0.000367573 0.690779" mass="0.554" diaginertia="0.00171956 0.0015451 0.000279479"/>
                  <joint name="right_ankle_roll_joint" pos="0 0 0" axis="1 0 0" range="-0.2618 0.2618"/>
                  <geom type="mesh" contype="0" conaffinity="0" group="1" density="0" rgba="0.698039 0.698039 0.698039 1" mesh="right_ankle_roll_link"/>
                  <geom size="0.005" pos="-0.05 0.025 -0.025" rgba="0.698039 0.698039 0.698039 1"/>
                  <geom size="0.005" pos="-0.05 -0.025 -0.025" rgba="0.698039 0.698039 0.698039 1"/>
                  <geom size="0.005" pos="0.12 0.03 -0.025" rgba="0.698039 0.698039 0.698039 1"/>
                  <geom size="0.005" pos="0.12 -0.03 -0.025" rgba="0.698039 0.698039 0.698039 1"/>
                </body>
              </body>
            </body>
          </body>
        </body>
      </body>
      <body name="waist_yaw_link" pos="0 0 0.1227">
        <inertial pos="-0.00013944 0.00328969 0.0562681" quat="0.706872 0.00612035 0.0272218 0.706791" mass="1.28" diaginertia="0.00197873 0.00138502 0.00129215"/>
        <!-- <joint name="waist_yaw_joint" pos="0 0 0" axis="0 0 1" range="-0.5236 0.5236"/> -->
        <geom type="mesh" contype="0" conaffinity="0" group="1" density="0" rgba="1 1 1 1" mesh="waist_yaw_link"/>
        <geom type="mesh" rgba="1 1 1 1" mesh="waist_yaw_link"/>
        <body name="waist_pitch_link" pos="0 0 0.0615">
          <inertial pos="-0.0179619 1.523e-05 0.187472" quat="0.99936 0.000168289 0.0357677 -5.38062e-05" mass="10.8" diaginertia="0.163501 0.140087 0.0751078"/>
          <!-- <joint name="waist_pitch_joint" pos="0 0 0" axis="0 1 0" range="-0.5236 0.5236"/> -->
          <geom type="mesh" contype="0" conaffinity="0" group="1" density="0" rgba="0.698039 0.698039 0.698039 1" mesh="waist_pitch_link"/>
          <geom type="mesh" rgba="0.698039 0.698039 0.698039 1" mesh="waist_pitch_link"/>
          <body name="left_shoulder_pitch_link" pos="0 0.155 0.318">
            <inertial pos="-0.00392068 -0.00730913 -1.42e-05" quat="0.690342 0.420284 0.575961 0.122714" mass="0.494" diaginertia="0.00033816 0.00033626 0.000302151"/>
            <!-- <joint name="left_shoulder_pitch_joint" pos="0 0 0" axis="0 1 0" range="-3.0892 2.6704" actuatorfrcrange="-36 36"/> -->
            <geom type="mesh" contype="0" conaffinity="0" group="1" density="0" rgba="0.698039 0.698039 0.698039 1" mesh="left_shoulder_pitch_link"/>
            <geom type="mesh" rgba="0.698039 0.698039 0.698039 1" mesh="left_shoulder_pitch_link"/>
            <body name="left_shoulder_roll_link">
              <inertial pos="0.0218027 0.00010593 -0.0397521" quat="0.990049 0.000410171 0.140708 -0.00176423" mass="0.08" diaginertia="7.70506e-05 7.41201e-05 2.06194e-05"/>
              <!-- <joint name="left_shoulder_roll_joint" pos="0 0 0" axis="1 0 0" range="-0.5236 2.2427" actuatorfrcrange="-36 36"/> -->
              <geom type="mesh" contype="0" conaffinity="0" group="1" density="0" rgba="0.698039 0.698039 0.698039 1" mesh="left_shoulder_roll_link"/>
              <geom type="mesh" rgba="0.698039 0.698039 0.698039 1" mesh="left_shoulder_roll_link"/>
              <body name="left_shoulder_yaw_link" pos="-0.0005 0 -0.07">
                <inertial pos="-0.00056731 0.00021413 -0.0736816" quat="0.69829 -0.0603687 -0.0624714 0.710523" mass="1.017" diaginertia="0.00240056 0.00236861 0.000671463"/>
                <!-- <joint name="left_shoulder_yaw_joint" pos="0 0 0" axis="0 0 1" range="-2.618 2.618" actuatorfrcrange="-36 36"/> -->
                <geom type="mesh" contype="0" conaffinity="0" group="1" density="0" rgba="0.698039 0.698039 0.698039 1" mesh="left_shoulder_yaw_link"/>
                <geom type="mesh" rgba="0.698039 0.698039 0.698039 1" mesh="left_shoulder_yaw_link"/>
                <body name="left_arm_pitch_link" pos="0.015 0.03175 -0.115">
                  <inertial pos="0.121971 -0.0214102 -0.00831472" quat="-0.0535585 0.699625 -0.12812 0.700886" mass="0.118" diaginertia="0.000891985 0.000888486 3.72783e-05"/>
                  <!-- <joint name="left_arm_pitch_joint" pos="0 0 0" axis="0 1 0" range="-1.0472 2.0944" actuatorfrcrange="-36 36"/> -->
                  <geom type="mesh" contype="0" conaffinity="0" group="1" density="0" rgba="0.698039 0.698039 0.698039 1" mesh="left_arm_pitch_link"/>
                  <geom type="mesh" rgba="0.698039 0.698039 0.698039 1" mesh="left_arm_pitch_link"/>
                </body>
              </body>
            </body>
          </body>
          <body name="right_shoulder_pitch_link" pos="0 -0.155 0.318">
            <inertial pos="-0.00392069 0.00730929 3.912e-05" quat="0.55809 0.150731 0.685507 0.442602" mass="0.504" diaginertia="0.000344229 0.000343844 0.000308267"/>
            <!-- <joint name="right_shoulder_pitch_joint" pos="0 0 0" axis="0 1 0" range="-3.0892 2.6704" actuatorfrcrange="-36 36"/> -->
            <geom type="mesh" contype="0" conaffinity="0" group="1" density="0" rgba="0.698039 0.698039 0.698039 1" mesh="right_shoulder_pitch_link"/>
            <geom type="mesh" rgba="0.698039 0.698039 0.698039 1" mesh="right_shoulder_pitch_link"/>
            <body name="right_shoulder_roll_link">
              <inertial pos="0.0218027 -0.00010593 -0.0397521" quat="0.990049 -0.000410171 0.140708 0.00176423" mass="0.08" diaginertia="7.70506e-05 7.41201e-05 2.06194e-05"/>
              <!-- <joint name="right_shoulder_roll_joint" pos="0 0 0" axis="1 0 0" range="-2.2427 0.5236" actuatorfrcrange="-36 36"/> -->
              <geom type="mesh" contype="0" conaffinity="0" group="1" density="0" rgba="0.698039 0.698039 0.698039 1" mesh="right_shoulder_roll_link"/>
              <geom type="mesh" rgba="0.698039 0.698039 0.698039 1" mesh="right_shoulder_roll_link"/>
              <body name="right_shoulder_yaw_link" pos="-0.0005 0 -0.07">
                <inertial pos="-0.00056753 -0.00019977 -0.0736671" quat="0.709484 -0.0626855 -0.0601504 0.699346" mass="1.017" diaginertia="0.00239935 0.00236738 0.000671486"/>
                <!-- <joint name="right_shoulder_yaw_joint" pos="0 0 0" axis="0 0 1" range="-2.618 2.618" actuatorfrcrange="-36 36"/> -->
                <geom type="mesh" contype="0" conaffinity="0" group="1" density="0" rgba="0.698039 0.698039 0.698039 1" mesh="right_shoulder_yaw_link"/>
                <geom type="mesh" rgba="0.698039 0.698039 0.698039 1" mesh="right_shoulder_yaw_link"/>
                <body name="right_arm_pitch_link" pos="0.015 -0.03175 -0.115">
                  <inertial pos="0.121971 0.0214102 -0.00831585" quat="0.0550009 0.699354 0.129564 0.70078" mass="0.119" diaginertia="0.000899566 0.000896027 3.7587e-05"/>
                  <!-- <joint name="right_arm_pitch_joint" pos="0 0 0" axis="0 1 0" range="-1.0472 2.0944" actuatorfrcrange="-36 36"/> -->
                  <geom type="mesh" contype="0" conaffinity="0" group="1" density="0" rgba="0.698039 0.698039 0.698039 1" mesh="right_arm_pitch_link"/>
                  <geom type="mesh" rgba="0.698039 0.698039 0.698039 1" mesh="right_arm_pitch_link"/>
                </body>
              </body>
            </body>
          </body>
        </body>
      </body>
    </body>
  </worldbody>
  <actuator>
    <motor name="left_hip_pitch_joint" joint="left_hip_pitch_joint" gear="1" ctrllimited="true" ctrlrange="-130 130"/>
    <motor name="left_hip_roll_joint" joint="left_hip_roll_joint" gear="1" ctrllimited="true" ctrlrange="-130 130"/>
    <motor name="left_hip_yaw_joint" joint="left_hip_yaw_joint" gear="1" ctrllimited="true" ctrlrange="-90 90"/>
    <motor name="left_knee_joint" joint="left_knee_joint" gear="1" ctrllimited="true" ctrlrange="-150 150"/>
    <motor name="left_ankle_pitch_joint" joint="left_ankle_pitch_joint" gear="1" ctrllimited="true" ctrlrange="-75 75"/>
    <motor name="left_ankle_roll_joint" joint="left_ankle_roll_joint" gear="1" ctrllimited="true" ctrlrange="-75 75"/>

    <motor name="right_hip_pitch_joint" joint="right_hip_pitch_joint" gear="1" ctrllimited="true" ctrlrange="-130 130"/>
    <motor name="right_hip_roll_joint" joint="right_hip_roll_joint" gear="1" ctrllimited="true" ctrlrange="-130 130"/>
    <motor name="right_hip_yaw_joint" joint="right_hip_yaw_joint" gear="1" ctrllimited="true" ctrlrange="-90 90"/>
    <motor name="right_knee_joint" joint="right_knee_joint" gear="1" ctrllimited="true" ctrlrange="-150 150"/>
    <motor name="right_ankle_pitch_joint" joint="right_ankle_pitch_joint" gear="1" ctrllimited="true" ctrlrange="-75 75"/>
    <motor name="right_ankle_roll_joint" joint="right_ankle_roll_joint" gear="1" ctrllimited="true" ctrlrange="-75 75"/>
  </actuator>

     <sensor>
        <framequat     name='orientation' objtype='site' noise='0.001' objname='imu_in_base'/>
        <framepos     name='position' objtype='site' noise='0.001' objname='imu_in_base'/>
        <gyro          name='angular-velocity'    site='imu_in_base' noise='0.005' cutoff='34.9'/>
        <velocimeter   name='linear-velocity'     site='imu_in_base' noise='0.001' cutoff='30'/>
        <accelerometer name='linear-acceleration' site='imu_in_base' noise='0.005' cutoff='157'/>
        <magnetometer  name='magnetometer'        site='imu_in_base'/>
    </sensor>

</mujoco>
