<?xml version="1.0" encoding="utf-8"?>
<!--此模型的质量与调试实机（电池为配置块）一致，具体真机与模型的质量（和转动惯量）差距可查询下表：https://doc.weixin.qq.com/sheet/e3_AR8AEwZRADES6grVgyMS0KevhxvMY?scode=AGsANQfPAAcTd0BvZ4 -->
<robot name="R2">
  <mujoco>
    <compiler meshdir="meshes/" balanceinertia="true" discardvisual="false" />
  </mujoco>

  <!-- [CAUTION] uncomment when convert to mujoco -->
  <!-- <link name="world"></link>
  <joint name="floating_base_joint" type="floating">
    <parent link="world"/>
    <child link="base_link"/>
  </joint> -->

  <link name="base_link">
    <inertial>
      <origin xyz="0.00327496 2.04e-06 0.0337905" rpy="0 0 0" />
      <mass value="3.335" />
      <inertia ixx="0.01261804" ixy="1.46e-06" ixz="-0.00010329" iyy="0.01128787" iyz="1.638e-05" izz="0.00585595" />
    </inertial>
    <visual>
      <origin xyz="0 0 0" rpy="0 0 0" />
      <geometry>
        <mesh filename="meshes/base_link.STL" />
      </geometry>
      <material name="">
        <color rgba="0.69804 0.69804 0.69804 1" />
      </material>
    </visual>
    <collision>
      <origin xyz="0 0 0" rpy="0 0 0" />
      <geometry>
        <mesh filename="meshes/base_link.STL" />
      </geometry>
    </collision>
  </link>
  <link name="left_hip_pitch_link">
    <inertial>
      <origin xyz="-0.00028938 0.05520985 0.00013118" rpy="0 0 0" />
      <mass value="1.213" />
      <inertia ixx="0.00188482" ixy="1.784e-05" ixz="0.00022231" iyy="0.00118886" iyz="-1.011e-05" izz="0.00134031" />
    </inertial>
    <visual>
      <origin xyz="0 0 0" rpy="0 0 0" />
      <geometry>
        <mesh filename="meshes/left_hip_pitch_link.STL" />
      </geometry>
      <material name="">
        <color rgba="0.698039215686274 0.698039215686274 0.698039215686274 1" />
      </material>
    </visual>
    <collision>
      <origin xyz="0 0 0" rpy="0 0 0" />
      <geometry>
        <mesh filename="meshes/left_hip_pitch_link.STL" />
      </geometry>
    </collision>
  </link>
  <joint name="left_hip_pitch_joint" type="revolute">
    <origin xyz="0 0.0584500002241198 0" rpy="0 0 0" />
    <parent link="base_link" />
    <child link="left_hip_pitch_link" />
    <axis xyz="0 1 0" />
    <limit lower="-2.530727415" upper="2.879793266" effort="130" velocity="14.658" />
    <dynamics damping="0" friction="0" />
  </joint>
  <link name="left_hip_roll_link">
    <inertial>
      <origin xyz="-0.01609958 -1.412e-05 -0.07854252" rpy="0 0 0" />
      <mass value="1.41" />
      <inertia ixx="0.00343001" ixy="1.135e-05" ixz="-0.00085477" iyy="0.00366739" iyz="-3e-08" izz="0.00223593" />
    </inertial>
    <visual>
      <origin xyz="0 0 0" rpy="0 0 0" />
      <geometry>
        <mesh filename="meshes/left_hip_roll_link.STL" />
      </geometry>
      <material name="">
        <color rgba="0.698039215686274 0.698039215686274 0.698039215686274 1" />
      </material>
    </visual>
    <collision>
      <origin xyz="0 0 0" rpy="0 0 0" />
      <geometry>
        <mesh filename="meshes/left_hip_roll_link.STL" />
      </geometry>
    </collision>
  </link>
  <joint name="left_hip_roll_joint" type="revolute">
    <origin xyz="0.0249722852796248 0.0615000000000107 0.0090893131122475" rpy="0 -0.349065850398729 0" />
    <parent link="left_hip_pitch_link" />
    <child link="left_hip_roll_link" />
    <axis xyz="1 0 0" />
    <limit lower="-0.2618" upper="2.4435" effort="130" velocity="14.658" />
    <dynamics damping="0" friction="0" />
  </joint>
  <link name="left_hip_yaw_link">
    <inertial>
      <origin xyz="-0.04741913 -0.00321393 -0.1557307" rpy="0 0 0" />
      <mass value="2.338" />
      <inertia ixx="0.01056771" ixy="-0.00014798" ixz="-0.00336716" iyy="0.01472501" iyz="-0.00022926" izz="0.00514596" />
    </inertial>
    <visual>
      <origin xyz="0 0 0" rpy="0 0 0" />
      <geometry>
        <mesh filename="meshes/left_hip_yaw_link.STL" />
      </geometry>
      <material name="">
        <color rgba="0.698039215686274 0.698039215686274 0.698039215686274 1" />
      </material>
    </visual>
    <collision>
      <origin xyz="0 0 0" rpy="0 0 0" />
      <geometry>
        <mesh filename="meshes/left_hip_yaw_link.STL" />
      </geometry>
    </collision>
  </link>
  <joint name="left_hip_yaw_joint" type="revolute">
    <origin xyz="-0.0267499999999739 0 -0.1225" rpy="0 0 0" />
    <parent link="left_hip_roll_link" />
    <child link="left_hip_yaw_link" />
    <axis xyz="0 0 1" />
    <limit lower="-2.7576" upper="2.7576" effort="90" velocity="16.438" />
    <dynamics damping="0" friction="0" />
  </joint>
  <link name="left_knee_link">
    <inertial>
      <origin xyz="-0.00155103 -0.01699974 -0.13563883" rpy="0 0 0" />
      <mass value="1.77" />
      <inertia ixx="0.0087247" ixy="-1.23e-05" ixz="-7.771e-05" iyy="0.00863491" iyz="-0.00073353" izz="0.0010461" />
    </inertial>
    <visual>
      <origin xyz="0 0 0" rpy="0 0 0" />
      <geometry>
        <mesh filename="meshes/left_knee_link.STL" />
      </geometry>
      <material name="">
        <color rgba="0.698039215686274 0.698039215686274 0.698039215686274 1" />
      </material>
    </visual>
    <collision>
      <origin xyz="0 0 0" rpy="0 0 0" />
      <geometry>
        <mesh filename="meshes/left_knee_link.STL" />
      </geometry>
    </collision>
  </link>
  <joint name="left_knee_joint" type="revolute">
    <origin xyz="-0.066694 0.02125 -0.18724" rpy="0 0.34907 0" />
    <parent link="left_hip_yaw_link" />
    <child link="left_knee_link" />
    <axis xyz="0 1 0" />
    <limit lower="-0.401425728" upper="2.42600766" effort="150" velocity="14.658" />
    <dynamics damping="0" friction="0" />
  </joint>
  <link name="left_ankle_pitch_link">
    <inertial>
      <origin xyz="-0.00174962 0.0 -0.0115014" rpy="0 0 0" />
      <mass value="0.09698402" />
      <inertia ixx="1.377e-05" ixy="-0.0" ixz="-1.35e-06" iyy="2.495e-05" iyz="-0.0" izz="1.58e-05" />
    </inertial>
    <visual>
      <origin xyz="0 0 0" rpy="0 0 0" />
      <geometry>
        <mesh filename="meshes/left_ankle_pitch_link.STL" />
      </geometry>
      <material name="">
        <color rgba="0.752941176470588 0.752941176470588 0.752941176470588 1" />
      </material>
    </visual>
    <collision>
      <origin xyz="0 0 0" rpy="0 0 0" />
      <geometry>
        <mesh filename="meshes/left_ankle_pitch_link.STL" />
      </geometry>
    </collision>
  </link>
  <joint name="left_ankle_pitch_joint" type="revolute">
    <origin xyz="0.00014288 -0.02125 -0.298" rpy="0 -0.00047947 0" />
    <parent link="left_knee_link" />
    <child link="left_ankle_pitch_link" />
    <axis xyz="0 1 0" />
    <limit lower="-0.69813" upper="0.5236" effort="75" velocity="12.25" />
    <dynamics damping="0" friction="0" />
  </joint>
  <link name="left_ankle_roll_link">
    <inertial>
      <origin xyz="0.00993838 -0.00011106 -0.01078381" rpy="0 0 0" />
      <mass value="0.49260375" />
      <inertia ixx="0.00017395" ixy="-1.455e-05" ixz="5.982e-05" iyy="0.0009755" iyz="-1.04e-06" izz="0.00101534" />
    </inertial>
    <visual>
      <origin xyz="0 0 0" rpy="0 0 0" />
      <geometry>
        <mesh filename="meshes/left_ankle_roll_arch_link.STL" />
      </geometry>
      <material name="">
        <color rgba="0.698039215686274 0.698039215686274 0.698039215686274 1" />
      </material>
    </visual>
    <!-- <collision>
      <origin xyz="0 0 0" rpy="0 0 0" />
      <geometry>
        <mesh filename="meshes/left_ankle_roll_arch_link.STL" />
      </geometry>
    </collision> -->

    <collision>
      <origin xyz="-0.05 -0.028 -0.025" rpy="0 0 0"/>
      <geometry>
        <sphere radius="0.005"/>
      </geometry>
    </collision>

    <collision>
      <origin xyz="-0.05 0.0185 -0.025" rpy="0 0 0"/>
      <geometry>
        <sphere radius="0.005"/>
      </geometry>
    </collision>

    <collision>
      <origin xyz="0.10 -0.026 -0.025" rpy="0 0 0"/>
      <geometry>
        <sphere radius="0.005"/>
      </geometry>
    </collision>

    <collision>
      <origin xyz="0.10 0.024 -0.025" rpy="0 0 0"/>
      <geometry>
        <sphere radius="0.005"/>
      </geometry>
    </collision>
  </link>
  <joint name="left_ankle_roll_joint" type="revolute">
    <origin xyz="0 0 -0.02" rpy="0 0 0" />
    <parent link="left_ankle_pitch_link" />
    <child link="left_ankle_roll_link" />
    <axis xyz="1 0 0" />
    <limit lower="-0.2618" upper="0.2618" effort="75" velocity="12.25" />
    <dynamics damping="0" friction="0" />
  </joint>
  <link name="right_hip_pitch_link">
    <inertial>
      <origin xyz="-0.00029784 -0.05483617 0.0002104" rpy="0 0 0" />
      <mass value="1.213" />
      <inertia ixx="0.00188697" ixy="-1.722e-05" ixz="0.00022111" iyy="0.00119139" iyz="1.074e-05" izz="0.00133822" />
    </inertial>
    <visual>
      <origin xyz="0 0 0" rpy="0 0 0" />
      <geometry>
        <mesh filename="meshes/right_hip_pitch_link.STL" />
      </geometry>
      <material name="">
        <color rgba="0.698039215686274 0.698039215686274 0.698039215686274 1" />
      </material>
    </visual>
    <collision>
      <origin xyz="0 0 0" rpy="0 0 0" />
      <geometry>
        <mesh filename="meshes/right_hip_pitch_link.STL" />
      </geometry>
    </collision>
  </link>
  <joint name="right_hip_pitch_joint" type="revolute">
    <origin xyz="0 -0.05845 0" rpy="0 0 0" />
    <parent link="base_link" />
    <child link="right_hip_pitch_link" />
    <axis xyz="0 1 0" />
    <limit lower="-2.530727415" upper="2.879793266" effort="130" velocity="14.658" />
    <dynamics damping="0" friction="0" />
  </joint>
  <link name="right_hip_roll_link">
    <inertial>
      <origin xyz="-0.01609958 -1.412e-05 -0.07854252" rpy="0 0 0" />
      <mass value="1.41" />
      <inertia ixx="0.00343001" ixy="1.135e-05" ixz="-0.00085477" iyy="0.00366739" iyz="-3e-08" izz="0.00223593" />
    </inertial>
    <visual>
      <origin xyz="0 0 0" rpy="0 0 0" />
      <geometry>
        <mesh filename="meshes/right_hip_roll_link.STL" />
      </geometry>
      <material name="">
        <color rgba="0.698039215686274 0.698039215686274 0.698039215686274 1" />
      </material>
    </visual>
    <collision>
      <origin xyz="0 0 0" rpy="0 0 0" />
      <geometry>
        <mesh filename="meshes/right_hip_roll_link.STL" />
      </geometry>
    </collision>
  </link>
  <joint name="right_hip_roll_joint" type="revolute">
    <origin xyz="0.0249723782195777 -0.0610999992992917 0.00908905776189617" rpy="0 -0.34906585039873 0" />
    <parent link="right_hip_pitch_link" />
    <child link="right_hip_roll_link" />
    <axis xyz="1 0 0" />
    <limit lower="-2.4435" upper="0.2618" effort="130" velocity="14.658" />
    <dynamics damping="0" friction="0" />
  </joint>
  <link name="right_hip_yaw_link">
    <inertial>
      <origin xyz="-0.04743498 0.00321447 -0.15572445" rpy="0 0 0" />
      <mass value="2.338" />
      <inertia ixx="0.01056519" ixy="0.00014855" ixz="-0.00337014" iyy="0.01472568" iyz="0.00022888" izz="0.00514912" />
    </inertial>
    <visual>
      <origin xyz="0 0 0" rpy="0 0 0" />
      <geometry>
        <mesh filename="meshes/right_hip_yaw_link.STL" />
      </geometry>
      <material name="">
        <color rgba="0.698039215686274 0.698039215686274 0.698039215686274 1" />
      </material>
    </visual>
    <collision>
      <origin xyz="0 0 0" rpy="0 0 0" />
      <geometry>
        <mesh filename="meshes/right_hip_yaw_link.STL" />
      </geometry>
    </collision>
  </link>
  <joint name="right_hip_yaw_joint" type="revolute">
    <origin xyz="-0.02675 0 -0.1225" rpy="0 0 0" />
    <parent link="right_hip_roll_link" />
    <child link="right_hip_yaw_link" />
    <axis xyz="0 0 1" />
    <limit lower="-2.7576" upper="2.7576" effort="90" velocity="16.438" />
    <dynamics damping="0" friction="0" />
  </joint>
  <link name="right_knee_link">
    <inertial>
      <origin xyz="-0.00155151 0.01700124 -0.13563996" rpy="0 0 0" />
      <mass value="1.771" />
      <inertia ixx="0.00872903" ixy="1.207e-05" ixz="-7.776e-05" iyy="0.00863907" iyz="0.00073381" izz="0.00104678" />
    </inertial>
    <visual>
      <origin xyz="0 0 0" rpy="0 0 0" />
      <geometry>
        <mesh filename="meshes/right_knee_link.STL" />
      </geometry>
      <material name="">
        <color rgba="0.698039215686274 0.698039215686274 0.698039215686274 1" />
      </material>
    </visual>
    <collision>
      <origin xyz="0 0 0" rpy="0 0 0" />
      <geometry>
        <mesh filename="meshes/right_knee_link.STL" />
      </geometry>
    </collision>
  </link>
  <joint name="right_knee_joint" type="revolute">
    <origin xyz="-0.066694 -0.02125 -0.18724" rpy="0 0.34907 0" />
    <parent link="right_hip_yaw_link" />
    <child link="right_knee_link" />
    <axis xyz="0 1 0" />
    <limit lower="-0.401425728" upper="2.42600766" effort="150" velocity="14.658" />
    <dynamics damping="0" friction="0" />
  </joint>
  <link name="right_ankle_pitch_link">
    <inertial>
      <origin xyz="-0.00174962 0.0 -0.0115014" rpy="0 0 0" />
      <mass value="0.09698402" />
      <inertia ixx="1.377e-05" ixy="-0.0" ixz="-1.35e-06" iyy="2.495e-05" iyz="-0.0" izz="1.58e-05" />
    </inertial>
    <visual>
      <origin xyz="0 0 0" rpy="0 0 0" />
      <geometry>
        <mesh filename="meshes/right_ankle_pitch_link.STL" />
      </geometry>
      <material name="">
        <color rgba="0.752941176470588 0.752941176470588 0.752941176470588 1" />
      </material>
    </visual>
    <collision>
      <origin xyz="0 0 0" rpy="0 0 0" />
      <geometry>
        <mesh filename="meshes/right_ankle_pitch_link.STL" />
      </geometry>
    </collision>
  </link>
  <joint name="right_ankle_pitch_joint" type="revolute">
    <origin xyz="0.000142882489459831 0.0212500000000541 -0.297999965745961" rpy="0 -0.000479471459510909 0" />
    <parent link="right_knee_link" />
    <child link="right_ankle_pitch_link" />
    <axis xyz="0 1 0" />
    <limit lower="-0.69813" upper="0.5236" effort="75" velocity="12.25" />
    <dynamics damping="0" friction="0" />
  </joint>
  <link name="right_ankle_roll_link">
    <inertial>
      <origin xyz="0.00994096 0.00011084 -0.01078409" rpy="0 0 0" />
      <mass value="0.49261348" />
      <inertia ixx="0.00017395" ixy="1.454e-05" ixz="5.984e-05" iyy="0.00097564" iyz="1.04e-06" izz="0.00101545" />
    </inertial>
    <visual>
      <origin xyz="0 0 0" rpy="0 0 0" />
      <geometry>
        <mesh filename="meshes/right_ankle_roll_arch_link.STL" />
      </geometry>
      <material name="">
        <color rgba="0.698039215686274 0.698039215686274 0.698039215686274 1" />
      </material>
    </visual>
    <!-- <collision>
      <origin xyz="0 0 0" rpy="0 0 0" />
      <geometry>
        <mesh filename="meshes/right_ankle_roll_arch_link.STL" />
      </geometry>
    </collision> -->

    <collision>
      <origin xyz="-0.05 0.028 -0.025" rpy="0 0 0"/>
      <geometry>
        <sphere radius="0.005"/>
      </geometry>
    </collision>

    <collision>
      <origin xyz="-0.05 -0.0185 -0.025" rpy="0 0 0"/>
      <geometry>
        <sphere radius="0.005"/>
      </geometry>
    </collision>

    <collision>
      <origin xyz="0.10 0.026 -0.025" rpy="0 0 0"/>
      <geometry>
        <sphere radius="0.005"/>
      </geometry>
    </collision>

    <collision>
      <origin xyz="0.10 -0.024 -0.025" rpy="0 0 0"/>
      <geometry>
        <sphere radius="0.005"/>
      </geometry>
    </collision>

  </link>
  <joint name="right_ankle_roll_joint" type="revolute">
    <origin xyz="0 0 -0.02" rpy="0 0 0" />
    <parent link="right_ankle_pitch_link" />
    <child link="right_ankle_roll_link" />
    <axis xyz="1 0 0" />
    <limit lower="-0.2618" upper="0.2618" effort="75" velocity="12.25" />
    <dynamics damping="0" friction="0" />
  </joint>
  <link name="waist_yaw_link">
    <inertial>
      <origin xyz="-0.00013944 0.00328969 0.05626813" rpy="0 0 0" />
      <mass value="1.28" />
      <inertia ixx="0.00138481" ixy="-4.8e-07" ixz="-4.36e-06" iyy="0.00197812" iyz="-2.047e-05" izz="0.00129297" />
    </inertial>
    <visual>
      <origin xyz="0 0 0" rpy="0 0 0" />
      <geometry>
        <mesh filename="meshes/waist_yaw_link.STL" />
      </geometry>
      <material name="">
        <color rgba="1 1 1 1" />
      </material>
    </visual>
    <collision>
      <origin xyz="0 0 0" rpy="0 0 0" />
      <geometry>
        <mesh filename="meshes/waist_yaw_link.STL" />
      </geometry>
    </collision>
  </link>
  <joint name="waist_yaw_joint" type="revolute">
    <origin xyz="0 0 0.122700000079517" rpy="0 0 0" />
    <parent link="base_link" />
    <child link="waist_yaw_link" />
    <axis xyz="0 0 1" />
    <limit lower="-0.5236" upper="0.5236" effort="90" velocity="16.438" />
    <dynamics damping="0" friction="0" />
  </joint>
  <link name="waist_pitch_link">
    <inertial>
      <origin xyz="-0.01796185 1.523e-05 0.18747235" rpy="0 0 0" />
      <mass value="10.8" />
      <inertia ixx="0.1630492" ixy="-6.5e-07" ixz="-0.00630302" iyy="0.14008728" iyz="2.221e-05" izz="0.0755596" />
    </inertial>
    <visual>
      <origin xyz="0 0 0" rpy="0 0 0" />
      <geometry>
        <mesh filename="meshes/waist_pitch_link.STL" />
      </geometry>
      <material name="">
        <color rgba="0.698039215686274 0.698039215686274 0.698039215686274 1" />
      </material>
    </visual>
    <collision>
      <origin xyz="0 0 0" rpy="0 0 0" />
      <geometry>
        <mesh filename="meshes/waist_pitch_link.STL" />
      </geometry>
    </collision>
  </link>
  <joint name="waist_pitch_joint" type="fixed">
    <origin xyz="0 0 0.0615" rpy="0 0 0" />
    <parent link="waist_yaw_link" />
    <child link="waist_pitch_link" />
    <axis xyz="0 1 0" />
    <limit lower="-0.5236" upper="0.5236" effort="90" velocity="16.438" />
    <dynamics damping="0" friction="0" />
  </joint>
  <link name="left_shoulder_pitch_link">
    <inertial>
      <origin xyz="-0.00392068 -0.00730913 -1.42e-05" rpy="0 0 0" />
      <mass value="0.494" />
      <inertia ixx="0.00030891" ixy="1.383e-05" ixz="1.1e-07" iyy="0.0003305" iyz="-1.11e-06" izz="0.00033716" />
    </inertial>
    <visual>
      <origin xyz="0 0 0" rpy="0 0 0" />
      <geometry>
        <mesh filename="meshes/left_shoulder_pitch_link.STL" />
      </geometry>
      <material name="">
        <color rgba="0.698039215686274 0.698039215686274 0.698039215686274 1" />
      </material>
    </visual>
    <collision>
      <origin xyz="0 0 0" rpy="0 0 0" />
      <geometry>
        <mesh filename="meshes/left_shoulder_pitch_link.STL" />
      </geometry>
    </collision>
  </link>
  <joint name="left_shoulder_pitch_joint" type="fixed">
    <origin xyz="0 0.154999999999985 0.318" rpy="0 0 0" />
    <parent link="waist_pitch_link" />
    <child link="left_shoulder_pitch_link" />
    <axis xyz="0 1 0" />
    <limit lower="-3.0892" upper="2.6704" effort="36" velocity="17.904" />
    <dynamics damping="0" friction="0" />
  </joint>
  <link name="left_shoulder_roll_link">
    <inertial>
      <origin xyz="0.02180272 0.00010593 -0.0397521" rpy="0 0 0" />
      <mass value="0.08" />
      <inertia ixx="7.267e-05" ixy="1e-08" ixz="-1.51e-05" iyy="7.412e-05" iyz="7e-08" izz="2.5e-05" />
    </inertial>
    <visual>
      <origin xyz="0 0 0" rpy="0 0 0" />
      <geometry>
        <mesh filename="meshes/left_shoulder_roll_link.STL" />
      </geometry>
      <material name="">
        <color rgba="0.698039215686274 0.698039215686274 0.698039215686274 1" />
      </material>
    </visual>
    <collision>
      <origin xyz="0 0 0" rpy="0 0 0" />
      <geometry>
        <mesh filename="meshes/left_shoulder_roll_link.STL" />
      </geometry>
    </collision>
  </link>
  <joint name="left_shoulder_roll_joint" type="fixed">
    <origin xyz="0 0 0" rpy="0 0 0" />
    <parent link="left_shoulder_pitch_link" />
    <child link="left_shoulder_roll_link" />
    <axis xyz="1 0 0" />
    <limit lower="-0.5236" upper="2.2427" effort="36" velocity="17.904" />
    <dynamics damping="0" friction="0" />
  </joint>
  <link name="left_shoulder_yaw_link">
    <inertial>
      <origin xyz="-0.00056731 0.00021413 -0.07368159" rpy="0 0 0" />
      <mass value="1.017" />
      <inertia ixx="0.00231781" ixy="-1.87e-06" ixz="0.00028923" iyy="0.00240052" iyz="7.51e-06" izz="0.00072231" />
    </inertial>
    <visual>
      <origin xyz="0 0 0" rpy="0 0 0" />
      <geometry>
        <mesh filename="meshes/left_shoulder_yaw_link.STL" />
      </geometry>
      <material name="">
        <color rgba="0.698039215686274 0.698039215686274 0.698039215686274 1" />
      </material>
    </visual>
    <collision>
      <origin xyz="0 0 0" rpy="0 0 0" />
      <geometry>
        <mesh filename="meshes/left_shoulder_yaw_link.STL" />
      </geometry>
    </collision>
  </link>
  <joint name="left_shoulder_yaw_joint" type="fixed">
    <origin xyz="-0.000500000000000125 0 -0.0699999999999965" rpy="0 0 0" />
    <parent link="left_shoulder_roll_link" />
    <child link="left_shoulder_yaw_link" />
    <axis xyz="0 0 1" />
    <limit lower="-2.618" upper="2.618" effort="36" velocity="17.904" />
    <dynamics damping="0" friction="0" />
  </joint>
  <link name="left_arm_pitch_link">
    <inertial>
      <origin xyz="0.12197121 -0.0214102 -0.00831472" rpy="0 0 0" />
      <mass value="0.118" />
      <inertia ixx="4.672e-05" ixy="8.86e-05" ixz="9.92e-06" iyy="0.00087939" iyz="-1.91e-06" izz="0.00089164" />
    </inertial>
    <visual>
      <origin xyz="0 0 0" rpy="0 0 0" />
      <geometry>
        <mesh filename="meshes/left_arm_pitch_link.STL" />
      </geometry>
      <material name="">
        <color rgba="0.698039215686274 0.698039215686274 0.698039215686274 1" />
      </material>
    </visual>
    <collision>
      <origin xyz="0 0 0" rpy="0 0 0" />
      <geometry>
        <mesh filename="meshes/left_arm_pitch_link.STL" />
      </geometry>
    </collision>
  </link>
  <joint name="left_arm_pitch_joint" type="fixed">
    <origin xyz="0.0150000000000026 0.0317500000000017 -0.115000000000002" rpy="0 0 0" />
    <parent link="left_shoulder_yaw_link" />
    <child link="left_arm_pitch_link" />
    <axis xyz="0 1 0" />
    <limit lower="-1.0472" upper="2.0944" effort="36" velocity="17.904" />
    <dynamics damping="0" friction="0" />
  </joint>
  <link name="right_shoulder_pitch_link">
    <inertial>
      <origin xyz="-0.00392069 0.00730929 3.912e-05" rpy="0 0 0" />
      <mass value="0.504" />
      <inertia ixx="0.00031516" ixy="-1.411e-05" ixz="-3.9e-07" iyy="0.00033719" iyz="-4e-07" izz="0.00034399" />
    </inertial>
    <visual>
      <origin xyz="0 0 0" rpy="0 0 0" />
      <geometry>
        <mesh filename="meshes/right_shoulder_pitch_link.STL" />
      </geometry>
      <material name="">
        <color rgba="0.698039215686274 0.698039215686274 0.698039215686274 1" />
      </material>
    </visual>
    <collision>
      <origin xyz="0 0 0" rpy="0 0 0" />
      <geometry>
        <mesh filename="meshes/right_shoulder_pitch_link.STL" />
      </geometry>
    </collision>
  </link>
  <joint name="right_shoulder_pitch_joint" type="fixed">
    <origin xyz="0 -0.15500000000002 0.318" rpy="0 0 0" />
    <parent link="waist_pitch_link" />
    <child link="right_shoulder_pitch_link" />
    <axis xyz="0 1 0" />
    <limit lower="-3.0892" upper="2.6704" effort="36" velocity="17.904" />
    <dynamics damping="0" friction="0" />
  </joint>
  <link name="right_shoulder_roll_link">
    <inertial>
      <origin xyz="0.02180272 -0.00010593 -0.0397521" rpy="0 0 0" />
      <mass value="0.08" />
      <inertia ixx="7.267e-05" ixy="-1e-08" ixz="-1.51e-05" iyy="7.412e-05" iyz="-7e-08" izz="2.5e-05" />
    </inertial>
    <visual>
      <origin xyz="0 0 0" rpy="0 0 0" />
      <geometry>
        <mesh filename="meshes/right_shoulder_roll_link.STL" />
      </geometry>
      <material name="">
        <color rgba="0.698039215686274 0.698039215686274 0.698039215686274 1" />
      </material>
    </visual>
    <collision>
      <origin xyz="0 0 0" rpy="0 0 0" />
      <geometry>
        <mesh filename="meshes/right_shoulder_roll_link.STL" />
      </geometry>
    </collision>
  </link>
  <joint name="right_shoulder_roll_joint" type="fixed">
    <origin xyz="0 0 0" rpy="0 0 0" />
    <parent link="right_shoulder_pitch_link" />
    <child link="right_shoulder_roll_link" />
    <axis xyz="1 0 0" />
    <limit lower="-2.2427" upper="0.5236" effort="36" velocity="17.904" />
    <dynamics damping="0" friction="0" />
  </joint>
  <link name="right_shoulder_yaw_link">
    <inertial>
      <origin xyz="-0.00056753 -0.00019977 -0.0736671" rpy="0 0 0" />
      <mass value="1.017" />
      <inertia ixx="0.00231661" ixy="1.88e-06" ixz="0.00028901" iyy="0.0023993" iyz="-8.12e-06" izz="0.0007223" />
    </inertial>
    <visual>
      <origin xyz="0 0 0" rpy="0 0 0" />
      <geometry>
        <mesh filename="meshes/right_shoulder_yaw_link.STL" />
      </geometry>
      <material name="">
        <color rgba="0.698039215686274 0.698039215686274 0.698039215686274 1" />
      </material>
    </visual>
    <collision>
      <origin xyz="0 0 0" rpy="0 0 0" />
      <geometry>
        <mesh filename="meshes/right_shoulder_yaw_link.STL" />
      </geometry>
    </collision>
  </link>
  <joint name="right_shoulder_yaw_joint" type="fixed">
    <origin xyz="-0.000500000000000017 0 -0.07" rpy="0 0 0" />
    <parent link="right_shoulder_roll_link" />
    <child link="right_shoulder_yaw_link" />
    <axis xyz="0 0 1" />
    <limit lower="-2.618" upper="2.618" effort="36" velocity="17.904" />
    <dynamics damping="0" friction="0" />
  </joint>
  <link name="right_arm_pitch_link">
    <inertial>
      <origin xyz="0.12197061 0.0214102 -0.00831585" rpy="0 0 0" />
      <mass value="0.119" />
      <inertia ixx="4.711e-05" ixy="-8.936e-05" ixz="9.99e-06" iyy="0.00088686" iyz="1.94e-06" izz="0.00089921" />
    </inertial>
    <visual>
      <origin xyz="0 0 0" rpy="0 0 0" />
      <geometry>
        <mesh filename="meshes/right_arm_pitch_link.STL" />
      </geometry>
      <material name="">
        <color rgba="0.698039215686274 0.698039215686274 0.698039215686274 1" />
      </material>
    </visual>
    <collision>
      <origin xyz="0 0 0" rpy="0 0 0" />
      <geometry>
        <mesh filename="meshes/right_arm_pitch_link.STL" />
      </geometry>
    </collision>
  </link>
  <joint name="right_arm_pitch_joint" type="fixed">
    <origin xyz="0.015000000000003 -0.0317499999999997 -0.115" rpy="0 0 0" />
    <parent link="right_shoulder_yaw_link" />
    <child link="right_arm_pitch_link" />
    <axis xyz="0 1 0" />
    <limit lower="-1.0472" upper="2.0944" effort="36" velocity="17.904" />
    <dynamics damping="0" friction="0" />
  </joint>

  <!-- imu -->
  <link name="imu_in_base"></link>
  <joint name="imu_in_base_joint" type="fixed">
    <origin xyz="0.0059965 -0.003397 -0.070175" rpy="0 0 0"/>
    <parent link="base_link"/>
    <child link="imu_in_base"/>
  </joint>

</robot>