<?xml version="1.0" encoding="utf-8"?>
<!-- 此模型用于仿真配重块版模型 -->
<robot name="R2">
  <mujoco>
    <compiler meshdir="meshes/" balanceinertia="true" discardvisual="false" />
  </mujoco>

  
  <!-- [CAUTION] uncomment when convert to mujoco -->
  <!-- <link name="world"></link>
  <joint name="floating_base_joint" type="floating">
    <parent link="world"/>
    <child link="base_link"/>
  </joint> -->

  <link name="base_link">
    <inertial>
      <origin xyz="0.00439618 5.853e-05 0.0065115" rpy="0 0 0" />
      <mass value="2.61" />
      <inertia ixx="0.00677361" ixy="2.89e-06" ixz="-0.00035304" iyy="0.00529171" iyz="-2.71e-06" izz="0.00502638" />
    </inertial>
    <visual>
      <origin xyz="0 0 0" rpy="0 0 0" />
      <geometry>
        <mesh filename="meshes/base_clump_weight_link.STL" />
      </geometry>
      <material name="">
        <color rgba="0.69804 0.69804 0.69804 1" />
      </material>
    </visual>
    <collision>
      <origin xyz="0 0 0" rpy="0 0 0" />
      <geometry>
        <mesh filename="meshes/base_clump_weight_link.STL" />
      </geometry>
    </collision>
  </link>
  <link name="clump_weight_link">
    <inertial>
      <origin xyz="-0.0006442 -7.046e-05 0.05178552" rpy="0 0 0" />
      <mass value="18.02929317" />
      <inertia ixx="0.05787748" ixy="-6.906e-05" ixz="-0.00072924" iyy="0.04960865" iyz="-1.088e-05" izz="0.06888179" />
    </inertial>
    <visual>
      <origin xyz="0 0 0" rpy="0 0 0" />
      <geometry>
        <mesh filename="meshes/clump_weight_link.STL" />
      </geometry>
      <material name="">
        <color rgba="0.69804 0.69804 0.69804 1" />
      </material>
    </visual>
    <collision>
      <origin xyz="0 0 0" rpy="0 0 0" />
      <geometry>
        <mesh filename="meshes/clump_weight_link.STL" />
      </geometry>
    </collision>
  </link>
  <joint name="clump_weight_joint" type="fixed">
    <origin xyz="0.0202500000012904 -0.00020855928995891 0.112124773455925" rpy="0 0 0" />
    <parent link="base_link" />
    <child link="clump_weight_link" />
  </joint>
  <link name="left_hip_pitch_link">
    <inertial>
      <origin xyz="-0.00028938 0.05520985 0.00013118" rpy="0 0 0" />
      <mass value="1.213" />
      <inertia ixx="0.00188482" ixy="1.784e-05" ixz="0.00022231" iyy="0.00118886" iyz="-1.011e-05" izz="0.00134031" />
    </inertial>
    <visual>
      <origin xyz="0 0 0" rpy="0 0 0" />
      <geometry>
        <mesh filename="meshes/left_hip_pitch_link.STL" />
      </geometry>
      <material name="">
        <color rgba="0.698039215686274 0.698039215686274 0.698039215686274 1" />
      </material>
    </visual>
    <collision>
      <origin xyz="0 0 0" rpy="0 0 0" />
      <geometry>
        <mesh filename="meshes/left_hip_pitch_link.STL" />
      </geometry>
    </collision>
  </link>
  <joint name="left_hip_pitch_joint" type="revolute">
    <origin xyz="0 0.0584500002241198 0" rpy="0 0 0" />
    <parent link="base_link" />
    <child link="left_hip_pitch_link" />
    <axis xyz="0 1 0" />
    <limit lower="-2.530727415" upper="2.879793266" effort="130" velocity="14.658" />
    <dynamics damping="0" friction="0" />
  </joint>
  <link name="left_hip_roll_link">
    <inertial>
      <origin xyz="-0.01609958 -1.412e-05 -0.07854252" rpy="0 0 0" />
      <mass value="1.41" />
      <inertia ixx="0.00343001" ixy="1.135e-05" ixz="-0.00085477" iyy="0.00366739" iyz="-3e-08" izz="0.00223593" />
    </inertial>
    <visual>
      <origin xyz="0 0 0" rpy="0 0 0" />
      <geometry>
        <mesh filename="meshes/left_hip_roll_link.STL" />
      </geometry>
      <material name="">
        <color rgba="0.698039215686274 0.698039215686274 0.698039215686274 1" />
      </material>
    </visual>
    <collision>
      <origin xyz="0 0 0" rpy="0 0 0" />
      <geometry>
        <mesh filename="meshes/left_hip_roll_link.STL" />
      </geometry>
    </collision>
  </link>
  <joint name="left_hip_roll_joint" type="revolute">
    <origin xyz="0.0249722852796248 0.0615000000000107 0.0090893131122475" rpy="0 -0.349065850398729 0" />
    <parent link="left_hip_pitch_link" />
    <child link="left_hip_roll_link" />
    <axis xyz="1 0 0" />
    <limit lower="-0.2618" upper="2.4435" effort="130" velocity="14.658" />
    <dynamics damping="0" friction="0" />
  </joint>
  <link name="left_hip_yaw_link">
    <inertial>
      <origin xyz="-0.04741913 -0.00321393 -0.1557307" rpy="0 0 0" />
      <mass value="2.338" />
      <inertia ixx="0.01056771" ixy="-0.00014798" ixz="-0.00336716" iyy="0.01472501" iyz="-0.00022926" izz="0.00514596" />
    </inertial>
    <visual>
      <origin xyz="0 0 0" rpy="0 0 0" />
      <geometry>
        <mesh filename="meshes/left_hip_yaw_link.STL" />
      </geometry>
      <material name="">
        <color rgba="0.698039215686274 0.698039215686274 0.698039215686274 1" />
      </material>
    </visual>
    <collision>
      <origin xyz="0 0 0" rpy="0 0 0" />
      <geometry>
        <mesh filename="meshes/left_hip_yaw_link.STL" />
      </geometry>
    </collision>
  </link>
  <joint name="left_hip_yaw_joint" type="revolute">
    <origin xyz="-0.0267499999999739 0 -0.1225" rpy="0 0 0" />
    <parent link="left_hip_roll_link" />
    <child link="left_hip_yaw_link" />
    <axis xyz="0 0 1" />
    <limit lower="-2.7576" upper="2.7576" effort="90" velocity="16.438" />
    <dynamics damping="0" friction="0" />
  </joint>
  <link name="left_knee_link">
    <inertial>
      <origin xyz="-0.00155103 -0.01699974 -0.13563883" rpy="0 0 0" />
      <mass value="1.77" />
      <inertia ixx="0.0087247" ixy="-1.23e-05" ixz="-7.771e-05" iyy="0.00863491" iyz="-0.00073353" izz="0.0010461" />
    </inertial>
    <visual>
      <origin xyz="0 0 0" rpy="0 0 0" />
      <geometry>
        <mesh filename="meshes/left_knee_link.STL" />
      </geometry>
      <material name="">
        <color rgba="0.698039215686274 0.698039215686274 0.698039215686274 1" />
      </material>
    </visual>
    <collision>
      <origin xyz="0 0 0" rpy="0 0 0" />
      <geometry>
        <mesh filename="meshes/left_knee_link.STL" />
      </geometry>
    </collision>
  </link>
  <joint name="left_knee_joint" type="revolute">
    <origin xyz="-0.066694 0.02125 -0.18724" rpy="0 0.34907 0" />
    <parent link="left_hip_yaw_link" />
    <child link="left_knee_link" />
    <axis xyz="0 1 0" />
    <limit lower="-0.401425728" upper="2.42600766" effort="150" velocity="14.658" />
    <dynamics damping="0" friction="0" />
  </joint>
  <link name="left_ankle_pitch_link">
    <inertial>
      <origin xyz="-0.00174962 0.0 -0.0115014" rpy="0 0 0" />
      <mass value="0.09698402" />
      <inertia ixx="1.377e-05" ixy="-0.0" ixz="-1.35e-06" iyy="2.495e-05" iyz="-0.0" izz="1.58e-05" />
    </inertial>
    <visual>
      <origin xyz="0 0 0" rpy="0 0 0" />
      <geometry>
        <mesh filename="meshes/left_ankle_pitch_link.STL" />
      </geometry>
      <material name="">
        <color rgba="0.752941176470588 0.752941176470588 0.752941176470588 1" />
      </material>
    </visual>
    <collision>
      <origin xyz="0 0 0" rpy="0 0 0" />
      <geometry>
        <mesh filename="meshes/left_ankle_pitch_link.STL" />
      </geometry>
    </collision>
  </link>
  <joint name="left_ankle_pitch_joint" type="revolute">
    <origin xyz="0.00014288 -0.02125 -0.298" rpy="0 -0.00047947 0" />
    <parent link="left_knee_link" />
    <child link="left_ankle_pitch_link" />
    <axis xyz="0 1 0" />
    <limit lower="-0.69813" upper="0.5236" effort="75" velocity="12.25" />
    <dynamics damping="0" friction="0" />
  </joint>
  <link name="left_ankle_roll_link">
    <inertial>
      <origin xyz="0.02167647 3.015e-05 -0.01889859" rpy="0 0 0" />
      <mass value="0.554" />
      <inertia ixx="0.00028267" ixy="-3.5e-07" ixz="6.632e-05" iyy="0.00154568" iyz="1.7e-07" izz="0.00171664" />
    </inertial>
    <visual>
      <origin xyz="0 0 0" rpy="0 0 0" />
      <geometry>
        <mesh filename="meshes/left_ankle_roll_link.STL" />
      </geometry>
      <material name="">
        <color rgba="0.698039215686274 0.698039215686274 0.698039215686274 1" />
      </material>
    </visual>
    <!-- <collision>
      <origin xyz="0 0 0" rpy="0 0 0" />
      <geometry>
        <mesh filename="meshes/left_ankle_roll_link.STL" />
      </geometry>
    </collision> -->

    <collision>
      <origin xyz="-0.05 0.025 -0.025" rpy="0 0 0"/>
      <geometry>
        <sphere radius="0.005"/>
      </geometry>
    </collision>

    <collision>
      <origin xyz="-0.05 -0.025 -0.025" rpy="0 0 0"/>
      <geometry>
        <sphere radius="0.005"/>
      </geometry>
    </collision>

    <collision>
      <origin xyz="0.12 0.03 -0.025" rpy="0 0 0"/>
      <geometry>
        <sphere radius="0.005"/>
      </geometry>
    </collision>

    <collision>
      <origin xyz="0.12 -0.03 -0.025" rpy="0 0 0"/>
      <geometry>
        <sphere radius="0.005"/>
      </geometry>
    </collision>

  </link>
  <joint name="left_ankle_roll_joint" type="revolute">
    <origin xyz="0 0 -0.02" rpy="0 0 0" />
    <parent link="left_ankle_pitch_link" />
    <child link="left_ankle_roll_link" />
    <axis xyz="1 0 0" />
    <limit lower="-0.2618" upper="0.2618" effort="75" velocity="12.25" />
    <dynamics damping="0" friction="0" />
  </joint>
  <link name="right_hip_pitch_link">
    <inertial>
      <origin xyz="-0.00029784 -0.05483617 0.0002104" rpy="0 0 0" />
      <mass value="1.213" />
      <inertia ixx="0.00188697" ixy="-1.722e-05" ixz="0.00022111" iyy="0.00119139" iyz="1.074e-05" izz="0.00133822" />
    </inertial>
    <visual>
      <origin xyz="0 0 0" rpy="0 0 0" />
      <geometry>
        <mesh filename="meshes/right_hip_pitch_link.STL" />
      </geometry>
      <material name="">
        <color rgba="0.698039215686274 0.698039215686274 0.698039215686274 1" />
      </material>
    </visual>
    <collision>
      <origin xyz="0 0 0" rpy="0 0 0" />
      <geometry>
        <mesh filename="meshes/right_hip_pitch_link.STL" />
      </geometry>
    </collision>
  </link>
  <joint name="right_hip_pitch_joint" type="revolute">
    <origin xyz="0 -0.05845 0" rpy="0 0 0" />
    <parent link="base_link" />
    <child link="right_hip_pitch_link" />
    <axis xyz="0 1 0" />
    <limit lower="-2.530727415" upper="2.879793266" effort="130" velocity="14.658" />
    <dynamics damping="0" friction="0" />
  </joint>
  <link name="right_hip_roll_link">
    <inertial>
      <origin xyz="-0.01609958 -1.412e-05 -0.07854252" rpy="0 0 0" />
      <mass value="1.41" />
      <inertia ixx="0.00343001" ixy="1.135e-05" ixz="-0.00085477" iyy="0.00366739" iyz="-3e-08" izz="0.00223593" />
    </inertial>
    <visual>
      <origin xyz="0 0 0" rpy="0 0 0" />
      <geometry>
        <mesh filename="meshes/right_hip_roll_link.STL" />
      </geometry>
      <material name="">
        <color rgba="0.698039215686274 0.698039215686274 0.698039215686274 1" />
      </material>
    </visual>
    <collision>
      <origin xyz="0 0 0" rpy="0 0 0" />
      <geometry>
        <mesh filename="meshes/right_hip_roll_link.STL" />
      </geometry>
    </collision>
  </link>
  <joint name="right_hip_roll_joint" type="revolute">
    <origin xyz="0.0249723782195777 -0.0610999992992917 0.00908905776189617" rpy="0 -0.34906585039873 0" />
    <parent link="right_hip_pitch_link" />
    <child link="right_hip_roll_link" />
    <axis xyz="1 0 0" />
    <limit lower="-2.4435" upper="0.2618" effort="130" velocity="14.658" />
    <dynamics damping="0" friction="0" />
  </joint>
  <link name="right_hip_yaw_link">
    <inertial>
      <origin xyz="-0.04743498 0.00321447 -0.15572445" rpy="0 0 0" />
      <mass value="2.338" />
      <inertia ixx="0.01056519" ixy="0.00014855" ixz="-0.00337014" iyy="0.01472568" iyz="0.00022888" izz="0.00514912" />
    </inertial>
    <visual>
      <origin xyz="0 0 0" rpy="0 0 0" />
      <geometry>
        <mesh filename="meshes/right_hip_yaw_link.STL" />
      </geometry>
      <material name="">
        <color rgba="0.698039215686274 0.698039215686274 0.698039215686274 1" />
      </material>
    </visual>
    <collision>
      <origin xyz="0 0 0" rpy="0 0 0" />
      <geometry>
        <mesh filename="meshes/right_hip_yaw_link.STL" />
      </geometry>
    </collision>
  </link>
  <joint name="right_hip_yaw_joint" type="revolute">
    <origin xyz="-0.02675 0 -0.1225" rpy="0 0 0" />
    <parent link="right_hip_roll_link" />
    <child link="right_hip_yaw_link" />
    <axis xyz="0 0 1" />
    <limit lower="-2.7576" upper="2.7576" effort="90" velocity="16.438" />
    <dynamics damping="0" friction="0" />
  </joint>
  <link name="right_knee_link">
    <inertial>
      <origin xyz="-0.00155151 0.01700124 -0.13563996" rpy="0 0 0" />
      <mass value="1.771" />
      <inertia ixx="0.00872903" ixy="1.207e-05" ixz="-7.776e-05" iyy="0.00863907" iyz="0.00073381" izz="0.00104678" />
    </inertial>
    <visual>
      <origin xyz="0 0 0" rpy="0 0 0" />
      <geometry>
        <mesh filename="meshes/right_knee_link.STL" />
      </geometry>
      <material name="">
        <color rgba="0.698039215686274 0.698039215686274 0.698039215686274 1" />
      </material>
    </visual>
    <collision>
      <origin xyz="0 0 0" rpy="0 0 0" />
      <geometry>
        <mesh filename="meshes/right_knee_link.STL" />
      </geometry>
    </collision>
  </link>
  <joint name="right_knee_joint" type="revolute">
    <origin xyz="-0.066694 -0.02125 -0.18724" rpy="0 0.34907 0" />
    <parent link="right_hip_yaw_link" />
    <child link="right_knee_link" />
    <axis xyz="0 1 0" />
    <limit lower="-0.401425728" upper="2.42600766" effort="150" velocity="14.658" />
    <dynamics damping="0" friction="0" />
  </joint>
  <link name="right_ankle_pitch_link">
    <inertial>
      <origin xyz="-0.00174962 0.0 -0.0115014" rpy="0 0 0" />
      <mass value="0.09698402" />
      <inertia ixx="1.377e-05" ixy="-0.0" ixz="-1.35e-06" iyy="2.495e-05" iyz="-0.0" izz="1.58e-05" />
    </inertial>
    <visual>
      <origin xyz="0 0 0" rpy="0 0 0" />
      <geometry>
        <mesh filename="meshes/right_ankle_pitch_link.STL" />
      </geometry>
      <material name="">
        <color rgba="0.752941176470588 0.752941176470588 0.752941176470588 1" />
      </material>
    </visual>
    <collision>
      <origin xyz="0 0 0" rpy="0 0 0" />
      <geometry>
        <mesh filename="meshes/right_ankle_pitch_link.STL" />
      </geometry>
    </collision>
  </link>
  <joint name="right_ankle_pitch_joint" type="revolute">
    <origin xyz="0.000142882489459831 0.0212500000000541 -0.297999965745961" rpy="0 -0.000479471459510909 0" />
    <parent link="right_knee_link" />
    <child link="right_ankle_pitch_link" />
    <axis xyz="0 1 0" />
    <limit lower="-0.69813" upper="0.5236" effort="75" velocity="12.25" />
    <dynamics damping="0" friction="0" />
  </joint>
  <link name="right_ankle_roll_link">
    <inertial>
      <origin xyz="0.02171574 3.14e-05 -0.01892029" rpy="0 0 0" />
      <mass value="0.554" />
      <inertia ixx="0.00028248" ixy="-3.1e-07" ixz="6.567e-05" iyy="0.0015451" iyz="1.5e-07" izz="0.00171656" />
    </inertial>
    <visual>
      <origin xyz="0 0 0" rpy="0 0 0" />
      <geometry>
        <mesh filename="meshes/right_ankle_roll_link.STL" />
      </geometry>
      <material name="">
        <color rgba="0.698039215686274 0.698039215686274 0.698039215686274 1" />
      </material>
    </visual>
    <!-- <collision>
      <origin xyz="0 0 0" rpy="0 0 0" />
      <geometry>
        <mesh filename="meshes/right_ankle_roll_link.STL" />
      </geometry>
    </collision> -->

    <collision>
      <origin xyz="-0.05 0.025 -0.025" rpy="0 0 0"/>
      <geometry>
        <sphere radius="0.005"/>
      </geometry>
    </collision>

    <collision>
      <origin xyz="-0.05 -0.025 -0.025" rpy="0 0 0"/>
      <geometry>
        <sphere radius="0.005"/>
      </geometry>
    </collision>

    <collision>
      <origin xyz="0.12 0.03 -0.025" rpy="0 0 0"/>
      <geometry>
        <sphere radius="0.005"/>
      </geometry>
    </collision>

    <collision>
      <origin xyz="0.12 -0.03 -0.025" rpy="0 0 0"/>
      <geometry>
        <sphere radius="0.005"/>
      </geometry>
    </collision>

  </link>
  <joint name="right_ankle_roll_joint" type="revolute">
    <origin xyz="0 0 -0.02" rpy="0 0 0" />
    <parent link="right_ankle_pitch_link" />
    <child link="right_ankle_roll_link" />
    <axis xyz="1 0 0" />
    <limit lower="-0.2618" upper="0.2618" effort="75" velocity="12.25" />
    <dynamics damping="0" friction="0" />
  </joint>

  <!-- imu -->
  <link name="imu_in_base"></link>
  <joint name="imu_in_base_joint" type="fixed">
    <origin xyz="0.0059965 -0.003397 -0.070175" rpy="0 0 0"/>
    <parent link="base_link"/>
    <child link="imu_in_base"/>
  </joint>

</robot>
